<?xml version="1.0" encoding="utf-8"?>
<!-- =================================================================================== -->
<!-- |    This document was autogenerated by xacro from urdf/3gdl.xacro                | -->
<!-- |    EDITING THIS FILE BY HAND IS NOT RECOMMENDED                                 | -->
<!-- =================================================================================== -->
<robot name="arm">
  <material name="mblue">
    <color rgba="0.1 0.1 0.8 1"/>
  </material>
  <material name="mred">
    <color rgba="0.8 0.1 0.1 1"/>
  </material>
  <material name="morange">
    <color rgba="1 0.5 0.1 1"/>
  </material>
  <link name="world"/>
  <link name="base_link">
    <visual>
      <origin rpy="0 0 0" xyz="0 0 0.05"/>
      <geometry>
        <cylinder length="0.1" radius="0.1"/>
      </geometry>
    </visual>
    <collision>
      <origin rpy="0 0 0" xyz="0 0 0.05"/>
      <geometry>
        <cylinder length="0.1" radius="0.1"/>
      </geometry>
    </collision>
    <inertial>
      <origin rpy="0 0 0" xyz="0 0 0.05"/>
      <mass value="1"/>
      <inertia ixx="0.00333333333333" ixy="0.0" ixz="0.0" iyy="0.00333333333333" iyz="0.0" izz="0.005"/>
    </inertial>
  </link>
  <link name="link_one">
    <visual>
      <origin rpy="0 0 0" xyz="0 0 0.075"/>
      <geometry>
        <cylinder length="0.15" radius="0.1"/>
      </geometry>
    </visual>
    <collision>
      <origin rpy="0 0 0" xyz="0 0 0.075"/>
      <geometry>
        <cylinder length="0.15" radius="0.1"/>
      </geometry>
    </collision>
    <inertial>
      <origin rpy="0 0 0" xyz="0 0 0.075"/>
      <mass value="0.7"/>
      <inertia ixx="0.0030625" ixy="0.0" ixz="0.0" iyy="0.0030625" iyz="0.0" izz="0.0035"/>
    </inertial>
  </link>
  <link name="link_two">
    <visual>
      <origin rpy="0 0 0" xyz="0 0 0.4"/>
      <geometry>
        <cylinder length="0.8" radius="0.1"/>
      </geometry>
    </visual>
    <collision>
      <origin rpy="0 0 0" xyz="0 0 0.4"/>
      <geometry>
        <cylinder length="0.8" radius="0.1"/>
      </geometry>
    </collision>
    <inertial>
      <origin rpy="0 0 0" xyz="0 0 0.4"/>
      <mass value="1"/>
      <inertia ixx="0.0558333333333" ixy="0.0" ixz="0.0" iyy="0.0558333333333" iyz="0.0" izz="0.005"/>
    </inertial>
  </link>
  <link name="link_three">
    <visual>
      <origin rpy="0 0 0" xyz="0 0 0.45"/>
      <geometry>
        <cylinder length="0.9" radius="0.1"/>
      </geometry>
    </visual>
    <collision>
      <origin rpy="0 0 0" xyz="0 0 0.45"/>
      <geometry>
        <cylinder length="0.9" radius="0.1"/>
      </geometry>
    </collision>
    <inertial>
      <origin rpy="0 0 0" xyz="0 0 0.45"/>
      <mass value="1"/>
      <inertia ixx="0.07" ixy="0.0" ixz="0.0" iyy="0.07" iyz="0.0" izz="0.005"/>
    </inertial>
  </link>
  <joint name="world_to_base" type="fixed">
    <parent link="world"/>
    <child link="base_link"/>
    <origin rpy="0 0 0" xyz="0 0 0"/>
  </joint>
  <joint name="shoulder_pan" type="continuous">
    <parent link="base_link"/>
    <child link="link_one"/>
    <origin rpy="0 0 0 " xyz="0 0 0.105"/>
    <axis xyz="0 0 1"/>
  </joint>
  <joint name="shoulder_tilt" type="continuous">
    <parent link="link_one"/>
    <child link="link_two"/>
    <origin rpy="0 0 0 " xyz="0 -0.22 0.15"/>
    <axis xyz="0 1 0"/>
  </joint>
  <joint name="elbow" type="continuous">
    <parent link="link_two"/>
    <child link="link_three"/>
    <origin rpy="0 1.57079632679 0 " xyz="0 0.22 0.8"/>
    <axis xyz="0 1 0"/>
  </joint>
  <gazebo reference="link_two">
    <material>Gazebo/Blue</material>
  </gazebo>
  <gazebo reference="link_three">
    <material>Gazebo/Red</material>
  </gazebo>
</robot>

