<?xml version="1.0" encoding="utf-8"?>
<robot name="pendulum">

  <material name="myblue">
    <color rgba="0.1 0.1 0.8 1"/>
  </material>

  <link name="world"/>
  
  <link name="base_link">
    <visual>
      <origin rpy="0 0 0" xyz="0 0 0.6"/>
      <geometry>
        <cylinder length="1.2" radius="0.1"/>
      </geometry>
      <material name="myblue"/>
    </visual>
    <collision>
      <origin rpy="0 0 0" xyz="0 0 0.6"/>
      <geometry>
        <cylinder length="1.2" radius="0.1"/>
      </geometry>
    </collision>
      <inertial>
      <origin rpy="0 0 0" xyz="0 0 0.6"/>
      <mass value="10"/>
      <inertia ixx="1"
	       iyy="1"
	       izz="0.05"
	       ixy="0.0" iyz="0.0" ixz="0.0"/>
    </inertial> 
  </link>

  <link name="link_one">
    <visual>
      <origin rpy="0 0 0" xyz="0 0 0.6"/>
      <geometry>
        <cylinder length="1.2" radius="0.1"/>
      </geometry>
    </visual>
    <collision>
      <origin rpy="0 0 0" xyz="0 0 0.6"/>
      <geometry>
        <cylinder length="1" radius="0.1"/>
      </geometry>
    </collision>
      <inertial>
      <origin rpy="0 0 0" xyz="0 0 0.6"/>
      <mass value="1"/>
      <inertia ixx="0.1"
	       iyy="0.1"
	       izz="0.005"
	       ixy="0.0" iyz="0.0" ixz="0.0"/>
    </inertial>
  </link>


  <joint name="world_to_base" type="fixed">
    <parent link="world"/>
    <child link="base_link"/>
    <origin rpy="0 0 0" xyz="0 0 0"/>
  </joint>
  
  <joint name="base_to_one" type="continuous">
    <parent link="base_link"/>
    <child link="link_one"/>
    <origin rpy="0 0 0 " xyz="0.25 0 1.1"/>
    <axis xyz="1 0 0"/>
  </joint>

   <gazebo reference="base_link">
    <material>Gazebo/Blue</material>
   </gazebo>
   <gazebo reference="link_one">
    <material>Gazebo/Red</material>
   </gazebo>
   
</robot>

